testing... b = 0
recovered[0] = 405662747
data[0] = 0
recovered[1] = 1749146347
data[1] = 0
recovered[2] = 826499306
data[2] = 0
recovered[3] = 1150855433
data[3] = 0
recovered[4] = 155252781
data[4] = 0
recovered[5] = 1019538883
data[5] = 0
recovered[6] = 1244309396
data[6] = 0
recovered[7] = 186325703
data[7] = 0
recovered[8] = 708920965
data[8] = 0
recovered[9] = 1221571882
data[9] = 0
recovered[10] = 311777938
data[10] = 0
recovered[11] = 459636836
data[11] = 0
recovered[12] = 1966176271
data[12] = 0
recovered[13] = 508408851
data[13] = 0
recovered[14] = 1976668886
data[14] = 0
recovered[15] = 1194733711
data[15] = 0
SIMDGlobalBinaryPacking+VariableByte
128
terminate called after throwing an instance of 'std::logic_error'
  what():  we have a bug
